<?xml version="1.0" ?>
<!-- =================================================================================== -->
<!-- |    This document was autogenerated by xacro from /home/martinapanini/Desktop/Giraffe_Robot/catkin_ws/src/giraffe_description/urdf/giraffe.urdf.xacro | -->
<!-- |    EDITING THIS FILE BY HAND IS NOT RECOMMENDED                                 | -->
<!-- =================================================================================== -->
<robot name="giraffe_robot">
  <!-- Materials -->
  <material name="black">
    <color rgba="0 0 0 1"/>
  </material>
  <material name="white">
    <color rgba="1 1 1 1"/>
  </material>
  <material name="dark grey">
    <color rgba="0 0 0 0.7"/>
  </material>
  <material name="light grey">
    <color rgba="0 0 0 0.5"/>
  </material>
  <link name="world"/>
  <!-- Base - Increased mass and corrected inertia -->
  <link name="base_link">
    <visual>
      <geometry>
        <box size="0.2 0.2 0.05"/>
      </geometry>
      <material name="white"/>
    </visual>
    <collision>
      <geometry>
        <box size="0.2 0.2 0.05"/>
      </geometry>
    </collision>
    <inertial>
      <mass value="5.0"/>
      <!-- Increased from 2.0 -->
      <origin xyz="0 0 0"/>
      <!-- Corrected inertia for box: I = 1/12*m*(y²+z²) -->
      <inertia ixx="0.00417" ixy="0" ixz="0" iyy="0.00417" iyz="0" izz="0.00833"/>
    </inertial>
  </link>
  <joint name="world_to_base" type="fixed">
    <parent link="world"/>
    <child link="base_link"/>
    <origin rpy="0 0 0" xyz="2.5 6.0 4.0"/>
  </joint>
  <!-- Link1: Pan - Corrected inertia for cylinder -->
  <link name="link1">
    <visual>
      <geometry>
        <cylinder length="0.1" radius="0.05"/>
      </geometry>
      <material name="dark grey"/>
    </visual>
    <collision>
      <geometry>
        <cylinder length="0.1" radius="0.05"/>
      </geometry>
    </collision>
    <inertial>
      <mass value="1.0"/>
      <origin xyz="0 0 0"/>
      <inertia ixx="0.00046" ixy="0" ixz="0" iyy="0.00046" iyz="0" izz="0.00125"/>
    </inertial>
  </link>
  <joint name="joint1" type="revolute">
    <parent link="base_link"/>
    <child link="link1"/>
    <origin rpy="0 0 0" xyz="0 0 0.025"/>
    <!-- Offset from base -->
    <axis xyz="0 0 1"/>
    <limit effort="100" lower="-3.141592653589793" upper="3.141592653589793" velocity="1"/>
    <dynamics damping="0.5"/>
  </joint>
  <!-- Link2: Tilt - Corrected inertia and COM -->
  <link name="link2">
    <visual>
      <geometry>
        <cylinder length="0.5" radius="0.03"/>
      </geometry>
      <origin rpy="0 1.5707963267948966 0" xyz="0.25 0 0"/>
      <material name="dark grey"/>
    </visual>
    <collision>
      <origin rpy="0 1.5707963267948966 0" xyz="0.25 0 0"/>
      <geometry>
        <cylinder length="0.5" radius="0.03"/>
      </geometry>
    </collision>
    <inertial>
      <mass value="2.0"/>
      <!-- Increased from 0.7 -->
      <origin xyz="0.25 0 0"/>
      <!-- COM at center -->
      <!-- For cylinder along x: Ixx = 1/2*m*r², Iyy=Izz=1/12*m*(3r²+L²) -->
      <inertia ixx="0.0009" ixy="0" ixz="0" iyy="0.0417" iyz="0" izz="0.0417"/>
    </inertial>
  </link>
  <joint name="joint2" type="revolute">
    <parent link="link1"/>
    <child link="link2"/>
    <origin rpy="0 0 0" xyz="0 0 0"/>
    <axis xyz="0 1 0"/>
    <limit effort="100" lower="-2.0943951023931953" upper="0" velocity="1"/>
    <!-- Reduced range -->
    <dynamics damping="0.5"/>
    <!-- Added damping -->
  </joint>
  <!-- Link3: Prismatic - Increased mass and corrected inertia -->
  <link name="link3">
    <visual>
      <geometry>
        <cylinder length="6.5" radius="0.03"/>
      </geometry>
      <origin rpy="0 1.5707963267948966 0" xyz="-3.25 0 0"/>
      <material name="dark grey"/>
    </visual>
    <collision>
      <geometry>
        <cylinder length="6.5" radius="0.03"/>
      </geometry>
      <origin rpy="0 1.5707963267948966 0" xyz="-3.25 0 0"/>
    </collision>
    <inertial>
      <mass value="1.5"/>
      <origin rpy="0 0 0" xyz="-3.25 0 0"/>
      <inertia ixx="0.0004" ixy="0" ixz="0" iyy="1.1252" iyz="0" izz="1.1252"/>
    </inertial>
  </link>
  <joint name="joint3" type="prismatic">
    <parent link="link2"/>
    <child link="link3"/>
    <origin rpy="0 0 0" xyz="0.5 0 0"/>
    <axis xyz="1 0 0"/>
    <limit effort="10000" lower="0" upper="6.5" velocity="0.5"/>
    <dynamics damping="10.0" friction="2.0"/>
    <!-- Increased damping -->
  </joint>
  <!-- Link4: Microphone bar - Corrected inertia -->
  <link name="link4">
    <visual>
      <geometry>
        <cylinder length="0.3" radius="0.025"/>
      </geometry>
      <origin rpy="0 1.5707963267948966 0" xyz="0.15 0 0"/>
      <material name="light grey"/>
    </visual>
    <collision>
      <origin rpy="0 1.5707963267948966 0" xyz="0.15 0 0"/>
      <geometry>
        <cylinder length="0.3" radius="0.01"/>
      </geometry>
    </collision>
    <inertial>
      <mass value="0.5"/>
      <!-- Increased from 0.1 -->
      <origin xyz="0.15 0 0"/>
      <!-- For cylinder along x: Ixx = 1/2*m*r², Iyy=Izz=1/12*m*(3r²+L²) -->
      <inertia ixx="0.000025" ixy="0" ixz="0" iyy="0.00377" iyz="0" izz="0.00377"/>
    </inertial>
  </link>
  <joint name="joint4" type="revolute">
    <parent link="link3"/>
    <child link="link4"/>
    <origin rpy="0 0 0" xyz="0 0 0"/>
    <axis xyz="0 1 0"/>
    <limit effort="50" lower="-1.5707963267948966" upper="1.5707963267948966" velocity="1"/>
    <dynamics damping="0.3"/>
  </joint>
  <!-- End-effector: microphone - Corrected inertia -->
  <link name="ee_link">
    <visual>
      <geometry>
        <sphere radius="0.025"/>
      </geometry>
      <material name="black"/>
    </visual>
    <visual>
      <geometry>
        <cylinder length="0.2" radius="0.008"/>
      </geometry>
      <origin rpy="0 0 0" xyz="0 0 -0.1"/>
      <material name="white"/>
    </visual>
    <visual>
      <geometry>
        <sphere radius="0.015"/>
      </geometry>
      <origin rpy="0 0 0" xyz="0 0 -0.2"/>
      <material name="black"/>
    </visual>
    <collision>
      <geometry>
        <sphere radius="0.03"/>
      </geometry>
    </collision>
    <inertial>
      <mass value="0.3"/>
      <origin xyz="0 0 -0.1"/>
      <inertia ixx="0.003" ixy="0" ixz="0" iyy="0.003" iyz="0" izz="0.003"/>
    </inertial>
  </link>
  <joint name="joint5" type="revolute">
    <parent link="link4"/>
    <child link="ee_link"/>
    <origin rpy="0 0 0" xyz="0.3 0 0"/>
    <axis xyz="0 1 0"/>
    <limit effort="50" lower="-1.5707963267948966" upper="1.5707963267948966" velocity="1"/>
    <dynamics damping="0.2"/>
  </joint>
</robot>
