<?xml version="1.0" ?>
<!-- =================================================================================== -->
<!-- |    This document was autogenerated by xacro from /home/martinapanini/Desktop/Giraffe_Robot/catkin_ws/src/giraffe_description/urdf/giraffe.urdf.xacro | -->
<!-- |    EDITING THIS FILE BY HAND IS NOT RECOMMENDED                                 | -->
<!-- =================================================================================== -->
<robot name="giraffe_robot">
  <!-- Materials -->
  <material name="gray">
    <color rgba="0 0 0 1"/>
  </material>
  <material name="red">
    <color rgba="1 0 0 1"/>
  </material>
  <material name="green">
    <color rgba="1 1 0 1"/>
  </material>
  <material name="blue">
    <color rgba="1 0 0 1"/>
  </material>
  <material name="yellow">
    <color rgba="1 1 0 1"/>
  </material>
  <material name="black">
    <color rgba="0 0 0 1"/>
  </material>
  <material name="white">
    <color rgba="1 1 1 1"/>
  </material>
  <link name="world"/>
  <!-- Base -->
  <link name="base_link">
    <visual>
      <geometry>
        <box size="0.2 0.2 0.05"/>
      </geometry>
      <material name="gray"/>
    </visual>
    <collision>
      <origin xyz="0 0 0"/>
      <geometry>
        <box size="0.2 0.2 0.05"/>
      </geometry>
    </collision>
    <inertial>
      <mass value="2.0"/>
      <origin xyz="0 0 0"/>
      <inertia ixx="0.003" ixy="0" ixz="0" iyy="0.003" iyz="0" izz="0.0005"/>
    </inertial>
  </link>
  <joint name="world_to_base" type="fixed">
    <parent link="world"/>
    <child link="base_link"/>
    <origin rpy="0 0 0" xyz="2.5 6.0 4.0"/>
  </joint>
  <!-- Link1: Pan -->
  <link name="link1">
    <visual>
      <geometry>
        <cylinder length="0.1" radius="0.05"/>
      </geometry>
      <material name="red"/>
    </visual>
    <collision>
      <origin xyz="0 0 0"/>
      <geometry>
        <cylinder length="0.1" radius="0.05"/>
      </geometry>
    </collision>
    <inertial>
      <mass value="0.3"/>
      <origin xyz="0 0 0"/>
      <inertia ixx="0.0001" ixy="0" ixz="0" iyy="0.0001" iyz="0" izz="0.0001"/>
    </inertial>
  </link>
  <joint name="joint1" type="revolute">
    <parent link="base_link"/>
    <child link="link1"/>
    <origin rpy="0 3.141592653589793 0" xyz="0 0 0"/>
    <axis xyz="0 0 1"/>
    <limit effort="100" lower="-3.141592653589793" upper="3.141592653589793" velocity="1"/>
  </joint>
  <!-- Link2: Tilt -->
  <link name="link2">
    <visual>
      <geometry>
        <cylinder length="0.5" radius="0.03"/>
      </geometry>
      <origin rpy="0 1.5707963267948966 0" xyz="0.25 0 0"/>
      <material name="green"/>
    </visual>
    <collision>
      <origin rpy="0 1.5707963267948966 0" xyz="0.25 0 0"/>
      <geometry>
        <cylinder length="0.5" radius="0.03"/>
      </geometry>
    </collision>
    <inertial>
      <mass value="0.7"/>
      <origin rpy="0 1.5707963267948966 0" xyz="0.25 0 0"/>
      <inertia ixx="0.002" ixy="0" ixz="0" iyy="0.002" iyz="0" izz="0.0005"/>
    </inertial>
  </link>
  <joint name="joint2" type="revolute">
    <parent link="link1"/>
    <child link="link2"/>
    <origin rpy="0 0 0" xyz="0 0 0"/>
    <axis xyz="0 1 0"/>
    <limit effort="100" lower="-3.141592653589793" upper="0" velocity="1"/>
  </joint>
  <!-- Link3: Prismatic -->
  <link name="link3">
    <visual>
      <geometry>
        <sphere radius="0.05"/>
      </geometry>
      <material name="blue"/>
    </visual>
    <collision>
      <origin xyz="0 0 0"/>
      <geometry>
        <sphere radius="0.05"/>
      </geometry>
    </collision>
    <inertial>
      <mass value="0.3"/>
      <origin xyz="0 0 0"/>
      <inertia ixx="0.0001" ixy="0" ixz="0" iyy="0.0001" iyz="0" izz="0.0001"/>
    </inertial>
  </link>
  <joint name="joint3" type="prismatic">
    <parent link="link2"/>
    <child link="link3"/>
    <origin rpy="0 0 0" xyz="0.5 0 0"/>
    <axis xyz="1 0 0"/>
    <limit effort="10000" lower="0" upper="6.5" velocity="0.5"/>
    <dynamics damping="5.0" friction="1.0"/>
  </joint>
  <!-- Link4: Microphone bar -->
  <link name="link4">
    <visual>
      <geometry>
        <cylinder length="0.3" radius="0.01"/>
      </geometry>
      <origin rpy="0 1.5707963267948966 0" xyz="0.15 0 0"/>
      <material name="yellow"/>
    </visual>
    <collision>
      <origin rpy="0 1.5707963267948966 0" xyz="0.15 0 0"/>
      <geometry>
        <cylinder length="0.3" radius="0.01"/>
      </geometry>
    </collision>
    <inertial>
      <mass value="0.1"/>
      <origin rpy="0 1.5707963267948966 0" xyz="0.15 0 0"/>
      <inertia ixx="0.00005" ixy="0" ixz="0" iyy="0.00005" iyz="0" izz="0.00002"/>
    </inertial>
  </link>
  <joint name="joint4" type="revolute">
    <parent link="link3"/>
    <child link="link4"/>
    <origin rpy="0 0 0" xyz="0.05 0 0"/>
    <axis xyz="0 1 0"/>
    <limit effort="50" lower="-1.5707963267948966" upper="1.5707963267948966" velocity="1"/>
  </joint>
  <!-- End-effector: microphone -->
  <link name="ee_link">
    <visual>
      <geometry>
        <box size="0.03 0.03 0.03"/>
      </geometry>
      <material name="black"/>
    </visual>
    <visual>
      <geometry>
        <cylinder length="0.2" radius="0.008"/>
      </geometry>
      <origin rpy="0 0 0" xyz="0 0 -0.1"/>
      <material name="white"/>
    </visual>
    <visual>
      <geometry>
        <sphere radius="0.015"/>
      </geometry>
      <origin rpy="0 0 0" xyz="0 0 -0.2"/>
      <material name="red"/>
    </visual>
    <collision>
      <origin rpy="0 0 0" xyz="0 0 -0.1"/>
      <geometry>
        <cylinder length="0.2" radius="0.015"/>
      </geometry>
    </collision>
    <inertial>
      <mass value="0.05"/>
      <origin rpy="0 0 0" xyz="0 0 -0.1"/>
      <inertia ixx="0.00001" ixy="0" ixz="0" iyy="0.00001" iyz="0" izz="0.000005"/>
    </inertial>
  </link>
  <joint name="joint5" type="revolute">
    <parent link="link4"/>
    <child link="ee_link"/>
    <origin rpy="0 0 0" xyz="0.3 0 0"/>
    <axis xyz="0 1 0"/>
    <limit effort="50" lower="-1.5707963267948966" upper="1.5707963267948966" velocity="1"/>
  </joint>
</robot>
